<?xml version="1.0"?>

<robot name="sailboat" xmlns:xacro="http://www.ros.org/wiki/xacro">

    <xacro:property name="PI" value="3.1415926535897931"/>

    <!-- HULL DESCRIPTION -->
    <link name="base_link">
        <visual>
          <origin rpy="1.57079632679 0 1.57079632679"/>
          <geometry>
            <mesh filename="package://sailboat_description/mesh/pt90.stl"/>
          </geometry>
          <material name="blue"/>
        </visual>

        <collision>
          <origin rpy="1.57079632679 0 1.57079632679"/>
          <geometry>
            <mesh filename="package://sailboat_description/mesh/pt90.stl"/>
          </geometry>
        </collision>

        <inertial>
            <origin rpy="0 0 0" xyz="0 0 -0.05"/>
          <mass value="10"/>
          <inertia ixx="0.1" ixy="0.0" ixz="0.0" iyy="1.4" iyz="0.0" izz="1.4"/>
        </inertial>

        <buoyancy>
          <compensation>1.2</compensation>
          <origin xyz="-0.0005 0 0.05"/>
          <limit radius="0.1"/>
          <damping rpy="20 50 50" xyz="20 50 50"/>
        </buoyancy>
    </link>

    <!-- RUDDER DESCRIPTION -->
    <link name="rudder">
            <inertial>
                <mass value="0.05" />
                <inertia
                  ixx="0.05"
                  ixy="0.0"
                  iyy="0.05"
                  ixz="0.0"
                  iyz="0.0"
                  izz="0.005"/>
            </inertial>

            <collision name="collision">
                <geometry>
                  <box size="0.1 0.02 0.3" />
                </geometry>
                <origin rpy="0 0 0" xyz="-0.1 0 0"/>
            </collision>

            <visual name="visual">
                <geometry>
                  <box size="0.1 0.02 0.3" />
                </geometry>
                <origin rpy="0 0 0" xyz="-0.1 0 0"/>
            </visual>
        </link>

        <joint name="rudder_joint" type="revolute">
            <parent link="base_link"/>
            <child link="rudder"/>
            <origin rpy="0 0 0" xyz="-0.53 0 -0.1"/>
            <dynamics damping="1.0"/>
            <axis xyz="0 0 1"/>
            <limit effort="50" velocity="5" lower="-${PI/3}" upper="${PI/3}" />
        </joint>

    <!-- SAIL DESCRIPTION -->
    <link name="sail">
		<inertial>
			<mass value="0.1" />
			<inertia
			  ixx="0.4708"
			  ixy="0.0"
			  iyy="0.5208"
			  ixz="0.0"
			  iyz="0.0"
			  izz="0.0508"/>
		</inertial>

	    <collision name="collision">
            <geometry>
              <box size="0.4 0.02 1" />
            </geometry>
            <origin rpy="0 0 0" xyz="0 0 0"/>
	    </collision>

	    <visual name="visual">
          <geometry>
            <mesh filename="package://sailboat_description/mesh/sail.dae"/>
          </geometry>
            <origin rpy="0 0 0" xyz="0 0 0"/>
	    </visual>

    </link>

    <joint name="sail_joint" type="revolute">
        <parent link="base_link"/>
        <child link="sail"/>
        <origin rpy="0 0 ${PI/2}" xyz="0 0 +0.6"/>
        <dynamics damping="1.0"/>
        <axis xyz="0 0 1"/>
        <limit effort="30" velocity="5" lower="-${PI/2}" upper="${PI/2}" />
    </joint>

</robot>
