<?xml version="1.0"?>

<robot name="sailboat" xmlns:xacro="http://www.ros.org/wiki/xacro">

    <xacro:property name="PI" value="3.1415926535897931"/>

    <!-- HULL DESCRIPTION -->
    <link name="base_link">
        <visual>
          <origin rpy="0 0 0"/>
          <geometry>
            <mesh filename="package://sailboat_description/mesh/pt90.stl"/>
          </geometry>
          <material name="blue"/>
        </visual>

        <collision>
          <origin rpy="0 0 0"/>
          <geometry>
            <mesh filename="package://sailboat_description/mesh/pt90.stl"/>
          </geometry>
        </collision>

        <inertial>
          <origin rpy="0 0 0" xyz="0 0 -0.05"/>
          <mass value="0.5"/>
          <inertia ixx="0.1" ixy="0.0" ixz="0.0" iyy="1.4" iyz="0.0" izz="1.4"/>
        </inertial>
    </link>

    <!-- RUDDER DESCRIPTION -->
    <link name="rudder">
            <inertial>
                <mass value="0.05" />
                <inertia
                  ixx="0.05"
                  ixy="0.0"
                  iyy="0.05"
                  ixz="0.0"
                  iyz="0.0"
                  izz="0.005"/>
            </inertial>

            <collision name="collision">
                <geometry>
                  <mesh filename="package://sailboat_description/mesh/rudder.stl"/>
                </geometry>
                <origin rpy="0 0 0" xyz="0.0 0 0"/>
            </collision>

            <visual name="visual">
                <geometry>
                  <mesh filename="package://sailboat_description/mesh/rudder.stl"/>
                </geometry>
                <origin rpy="0 0 0" xyz="0.0 0 0"/>
            </visual>
        </link>

        <joint name="rudder_joint" type="revolute">
            <parent link="base_link"/>
            <child link="rudder"/>
            <origin rpy="0 0 0" xyz="-0.4 0 0.0"/>
            <dynamics damping="1.0"/>
            <axis xyz="0 0 1"/>
            <limit effort="50" velocity="5" lower="-${PI/3}" upper="${PI/3}" />
        </joint>

    <!-- SAIL DESCRIPTION -->
    <link name="sail">
		<inertial>
			<mass value="0.1" />
			<inertia
			  ixx="0.4708"
			  ixy="0.0"
			  iyy="0.5208"
			  ixz="0.0"
			  iyz="0.0"
			  izz="0.0508"/>
		</inertial>

	    <collision name="collision">
            <geometry>
              <mesh filename="package://sailboat_description/mesh/sail.dae"/>
            </geometry>
            <origin rpy="0 0 0" xyz="0.0 0 0.0"/>
	    </collision>

	    <visual name="visual">
          <geometry>
            <mesh filename="package://sailboat_description/mesh/sail.dae"/>
          </geometry>
            <origin rpy="0 0 0" xyz="0.0 0 0.0"/>
	    </visual>

    </link>

    <joint name="sail_joint" type="revolute">
        <parent link="base_link"/>
        <child link="sail"/>
        <origin rpy="0 0 0" xyz="0.25 0 0.0"/>
        <dynamics damping="1.0"/>
        <axis xyz="0 0 1"/>
        <limit effort="30" velocity="5" lower="-${PI/2}" upper="${PI/2}" />
    </joint>



  <gazebo>
    <plugin name="gazebo_ros_control" filename="libgazebo_ros_control.so">
      <robotNamespace>/sailboat</robotNamespace>
    </plugin>
  </gazebo>

  <transmission name="sail_trans">
    <type>transmission_interface/SimpleTransmission</type>
    <actuator name="sail_act">
      <mechanicalReduction>1</mechanicalReduction>
    </actuator>
    <joint name="sail_joint">
      <hardwareInterface>hardware_interface/PositionJointInterface</hardwareInterface>
    </joint>
  </transmission>

  <transmission name="rudder_trans">
    <type>transmission_interface/SimpleTransmission</type>
    <actuator name="rudder_act">
      <mechanicalReduction>1</mechanicalReduction>
    </actuator>
    <joint name="rudder_joint">
      <hardwareInterface>hardware_interface/PositionJointInterface</hardwareInterface>
    </joint>
  </transmission>

</robot>
